[2019-11-12 13:37:40,390: WARNING/ForkPoolWorker-1] Request: <Context: {'lang': 'py', 'task': 'scheduler.celery.debug_task', 'id': 'e5ae1ff5-45cc-4474-a523-56b4bfdeec51', 'shadow': None, 'eta': None, 'expires': None, 'group': None, 'retries': 0, 'timelimit': [None, None], 'root_id': 'e5ae1ff5-45cc-4474-a523-56b4bfdeec51', 'parent_id': None, 'argsrepr': '()', 'kwargsrepr': '{}', 'origin': 'gen13279@prometheus', 'reply_to': 'c87a092e-c9da-3c66-97e9-af6adca4cf2c', 'correlation_id': 'e5ae1ff5-45cc-4474-a523-56b4bfdeec51', 'delivery_info': {'exchange': '', 'routing_key': 'celery', 'priority': 0, 'redelivered': False}, 'args': [], 'kwargs': {}, 'hostname': 'schdue@prometheus', 'is_eager': False, 'callbacks': None, 'errbacks': None, 'chain': None, 'chord': None, 'called_directly': False, '_protected': 1}>
[2019-11-12 13:37:40,473: INFO/ForkPoolWorker-1] Task scheduler.celery.debug_task[e5ae1ff5-45cc-4474-a523-56b4bfdeec51] succeeded in 0.08302453672513366s: None
[2019-11-12 13:38:00,401: WARNING/ForkPoolWorker-1] Request: <Context: {'lang': 'py', 'task': 'scheduler.celery.debug_task', 'id': '4aa5deef-afdf-4fc7-9a16-ce98d70c6e04', 'shadow': None, 'eta': None, 'expires': None, 'group': None, 'retries': 0, 'timelimit': [None, None], 'root_id': '4aa5deef-afdf-4fc7-9a16-ce98d70c6e04', 'parent_id': None, 'argsrepr': '()', 'kwargsrepr': '{}', 'origin': 'gen13279@prometheus', 'reply_to': 'c87a092e-c9da-3c66-97e9-af6adca4cf2c', 'correlation_id': '4aa5deef-afdf-4fc7-9a16-ce98d70c6e04', 'delivery_info': {'exchange': '', 'routing_key': 'celery', 'priority': 0, 'redelivered': False}, 'args': [], 'kwargs': {}, 'hostname': 'schdue@prometheus', 'is_eager': False, 'callbacks': None, 'errbacks': None, 'chain': None, 'chord': None, 'called_directly': False, '_protected': 1}>
[2019-11-12 13:38:00,431: INFO/ForkPoolWorker-1] Task scheduler.celery.debug_task[4aa5deef-afdf-4fc7-9a16-ce98d70c6e04] succeeded in 0.029828863218426704s: None
[2019-11-12 14:34:10,075: INFO/ForkPoolWorker-1] Task celery.backend_cleanup[201cb493-2cb4-4504-95e7-bd888c59ec17] succeeded in 0.03927868418395519s: None
[2019-11-12 15:22:23,401: WARNING/ForkPoolWorker-1] Request: <Context: {'lang': 'py', 'task': 'scheduler.celery.debug_task', 'id': 'd9b6f745-97a5-4b56-8041-aa752177d539', 'shadow': None, 'eta': None, 'expires': None, 'group': None, 'retries': 0, 'timelimit': [None, None], 'root_id': 'd9b6f745-97a5-4b56-8041-aa752177d539', 'parent_id': None, 'argsrepr': '()', 'kwargsrepr': '{}', 'origin': 'gen19415@prometheus', 'reply_to': '96e3833c-a271-36d2-8639-f49ecdc9c2ed', 'correlation_id': 'd9b6f745-97a5-4b56-8041-aa752177d539', 'delivery_info': {'exchange': '', 'routing_key': 'celery', 'priority': 0, 'redelivered': False}, 'args': [], 'kwargs': {}, 'hostname': 'schdue@prometheus', 'is_eager': False, 'callbacks': None, 'errbacks': None, 'chain': None, 'chord': None, 'called_directly': False, '_protected': 1}>
[2019-11-12 15:22:23,478: INFO/ForkPoolWorker-1] Task scheduler.celery.debug_task[d9b6f745-97a5-4b56-8041-aa752177d539] succeeded in 0.07770426385104656s: None
[2019-11-12 15:27:57,012: WARNING/ForkPoolWorker-1] Request: <Context: {'lang': 'py', 'task': 'scheduler.celery.debug_task', 'id': 'aa3e00d0-332e-4478-a131-65d1226a19cb', 'shadow': None, 'eta': None, 'expires': None, 'group': None, 'retries': 0, 'timelimit': [None, None], 'root_id': 'aa3e00d0-332e-4478-a131-65d1226a19cb', 'parent_id': None, 'argsrepr': '()', 'kwargsrepr': '{}', 'origin': 'gen20412@prometheus', 'reply_to': 'cf200f5b-3070-361b-9e3a-05aad4b74ac3', 'correlation_id': 'aa3e00d0-332e-4478-a131-65d1226a19cb', 'delivery_info': {'exchange': '', 'routing_key': 'celery', 'priority': 0, 'redelivered': False}, 'args': [], 'kwargs': {}, 'hostname': 'schdue@prometheus', 'is_eager': False, 'callbacks': None, 'errbacks': None, 'chain': None, 'chord': None, 'called_directly': False, '_protected': 1}>
[2019-11-12 15:27:57,130: INFO/ForkPoolWorker-1] Task scheduler.celery.debug_task[aa3e00d0-332e-4478-a131-65d1226a19cb] succeeded in 0.11828694026917219s: None
[2019-11-12 15:28:06,990: WARNING/ForkPoolWorker-1] Request: <Context: {'lang': 'py', 'task': 'scheduler.celery.debug_task', 'id': '58d3752b-fd5c-46e2-a1e5-b9e6aee6c15c', 'shadow': None, 'eta': None, 'expires': None, 'group': None, 'retries': 0, 'timelimit': [None, None], 'root_id': '58d3752b-fd5c-46e2-a1e5-b9e6aee6c15c', 'parent_id': None, 'argsrepr': '()', 'kwargsrepr': '{}', 'origin': 'gen20412@prometheus', 'reply_to': 'cf200f5b-3070-361b-9e3a-05aad4b74ac3', 'correlation_id': '58d3752b-fd5c-46e2-a1e5-b9e6aee6c15c', 'delivery_info': {'exchange': '', 'routing_key': 'celery', 'priority': 0, 'redelivered': False}, 'args': [], 'kwargs': {}, 'hostname': 'schdue@prometheus', 'is_eager': False, 'callbacks': None, 'errbacks': None, 'chain': None, 'chord': None, 'called_directly': False, '_protected': 1}>
[2019-11-12 15:28:07,081: INFO/ForkPoolWorker-1] Task scheduler.celery.debug_task[58d3752b-fd5c-46e2-a1e5-b9e6aee6c15c] succeeded in 0.09139371523633599s: None
[2019-11-12 15:28:16,993: WARNING/ForkPoolWorker-1] Request: <Context: {'lang': 'py', 'task': 'scheduler.celery.debug_task', 'id': 'c7a4a6f4-4039-425b-a36b-3e1e65e3593b', 'shadow': None, 'eta': None, 'expires': None, 'group': None, 'retries': 0, 'timelimit': [None, None], 'root_id': 'c7a4a6f4-4039-425b-a36b-3e1e65e3593b', 'parent_id': None, 'argsrepr': '()', 'kwargsrepr': '{}', 'origin': 'gen20412@prometheus', 'reply_to': 'cf200f5b-3070-361b-9e3a-05aad4b74ac3', 'correlation_id': 'c7a4a6f4-4039-425b-a36b-3e1e65e3593b', 'delivery_info': {'exchange': '', 'routing_key': 'celery', 'priority': 0, 'redelivered': False}, 'args': [], 'kwargs': {}, 'hostname': 'schdue@prometheus', 'is_eager': False, 'callbacks': None, 'errbacks': None, 'chain': None, 'chord': None, 'called_directly': False, '_protected': 1}>
[2019-11-12 15:28:17,033: INFO/ForkPoolWorker-1] Task scheduler.celery.debug_task[c7a4a6f4-4039-425b-a36b-3e1e65e3593b] succeeded in 0.040162968914955854s: None
[2019-11-12 15:28:26,997: WARNING/ForkPoolWorker-1] Request: <Context: {'lang': 'py', 'task': 'scheduler.celery.debug_task', 'id': 'edbd436f-727e-42a8-a057-cc54cdf046a7', 'shadow': None, 'eta': None, 'expires': None, 'group': None, 'retries': 0, 'timelimit': [None, None], 'root_id': 'edbd436f-727e-42a8-a057-cc54cdf046a7', 'parent_id': None, 'argsrepr': '()', 'kwargsrepr': '{}', 'origin': 'gen20412@prometheus', 'reply_to': 'cf200f5b-3070-361b-9e3a-05aad4b74ac3', 'correlation_id': 'edbd436f-727e-42a8-a057-cc54cdf046a7', 'delivery_info': {'exchange': '', 'routing_key': 'celery', 'priority': 0, 'redelivered': False}, 'args': [], 'kwargs': {}, 'hostname': 'schdue@prometheus', 'is_eager': False, 'callbacks': None, 'errbacks': None, 'chain': None, 'chord': None, 'called_directly': False, '_protected': 1}>
[2019-11-12 15:28:27,084: INFO/ForkPoolWorker-1] Task scheduler.celery.debug_task[edbd436f-727e-42a8-a057-cc54cdf046a7] succeeded in 0.08681777212768793s: None
[2019-11-12 15:28:36,999: WARNING/ForkPoolWorker-1] Request: <Context: {'lang': 'py', 'task': 'scheduler.celery.debug_task', 'id': '8711cdce-e6d3-40c2-8bcd-18d61d23d127', 'shadow': None, 'eta': None, 'expires': None, 'group': None, 'retries': 0, 'timelimit': [None, None], 'root_id': '8711cdce-e6d3-40c2-8bcd-18d61d23d127', 'parent_id': None, 'argsrepr': '()', 'kwargsrepr': '{}', 'origin': 'gen20412@prometheus', 'reply_to': 'cf200f5b-3070-361b-9e3a-05aad4b74ac3', 'correlation_id': '8711cdce-e6d3-40c2-8bcd-18d61d23d127', 'delivery_info': {'exchange': '', 'routing_key': 'celery', 'priority': 0, 'redelivered': False}, 'args': [], 'kwargs': {}, 'hostname': 'schdue@prometheus', 'is_eager': False, 'callbacks': None, 'errbacks': None, 'chain': None, 'chord': None, 'called_directly': False, '_protected': 1}>
[2019-11-12 15:28:37,037: INFO/ForkPoolWorker-1] Task scheduler.celery.debug_task[8711cdce-e6d3-40c2-8bcd-18d61d23d127] succeeded in 0.03800490312278271s: None
[2019-11-12 15:28:47,004: WARNING/ForkPoolWorker-1] Request: <Context: {'lang': 'py', 'task': 'scheduler.celery.debug_task', 'id': '7afe4780-1332-47d9-b12c-ec0edc79d193', 'shadow': None, 'eta': None, 'expires': None, 'group': None, 'retries': 0, 'timelimit': [None, None], 'root_id': '7afe4780-1332-47d9-b12c-ec0edc79d193', 'parent_id': None, 'argsrepr': '()', 'kwargsrepr': '{}', 'origin': 'gen20412@prometheus', 'reply_to': 'cf200f5b-3070-361b-9e3a-05aad4b74ac3', 'correlation_id': '7afe4780-1332-47d9-b12c-ec0edc79d193', 'delivery_info': {'exchange': '', 'routing_key': 'celery', 'priority': 0, 'redelivered': False}, 'args': [], 'kwargs': {}, 'hostname': 'schdue@prometheus', 'is_eager': False, 'callbacks': None, 'errbacks': None, 'chain': None, 'chord': None, 'called_directly': False, '_protected': 1}>
[2019-11-12 15:28:47,085: INFO/ForkPoolWorker-1] Task scheduler.celery.debug_task[7afe4780-1332-47d9-b12c-ec0edc79d193] succeeded in 0.08091747714206576s: None
[2019-11-12 15:31:00,014: WARNING/ForkPoolWorker-1] Request: <Context: {'lang': 'py', 'task': 'scheduler.celery.debug_task', 'id': '9b049e21-24fa-4cc7-8f80-c8432c454da6', 'shadow': None, 'eta': None, 'expires': None, 'group': None, 'retries': 0, 'timelimit': [None, None], 'root_id': '9b049e21-24fa-4cc7-8f80-c8432c454da6', 'parent_id': None, 'argsrepr': '()', 'kwargsrepr': '{}', 'origin': 'gen20412@prometheus', 'reply_to': 'cf200f5b-3070-361b-9e3a-05aad4b74ac3', 'correlation_id': '9b049e21-24fa-4cc7-8f80-c8432c454da6', 'delivery_info': {'exchange': '', 'routing_key': 'celery', 'priority': 0, 'redelivered': False}, 'args': [], 'kwargs': {}, 'hostname': 'schdue@prometheus', 'is_eager': False, 'callbacks': None, 'errbacks': None, 'chain': None, 'chord': None, 'called_directly': False, '_protected': 1}>
[2019-11-12 15:31:00,119: INFO/ForkPoolWorker-1] Task scheduler.celery.debug_task[9b049e21-24fa-4cc7-8f80-c8432c454da6] succeeded in 0.10557585209608078s: None
[2019-11-12 15:54:47,759: WARNING/ForkPoolWorker-1] Request: <Context: {'lang': 'py', 'task': 'scheduler.celery.debug_task', 'id': '0d5a15ff-893f-40ce-b689-3a8b7e2f9259', 'shadow': None, 'eta': None, 'expires': None, 'group': None, 'retries': 0, 'timelimit': [None, None], 'root_id': '0d5a15ff-893f-40ce-b689-3a8b7e2f9259', 'parent_id': None, 'argsrepr': '()', 'kwargsrepr': '{}', 'origin': 'gen22012@prometheus', 'reply_to': '75bbda84-2f2e-3fd8-b88b-fe27b3cab055', 'correlation_id': '0d5a15ff-893f-40ce-b689-3a8b7e2f9259', 'delivery_info': {'exchange': '', 'routing_key': 'celery', 'priority': 0, 'redelivered': False}, 'args': [], 'kwargs': {}, 'hostname': 'schdue@prometheus', 'is_eager': False, 'callbacks': None, 'errbacks': None, 'chain': None, 'chord': None, 'called_directly': False, '_protected': 1}>
[2019-11-12 15:54:47,818: INFO/ForkPoolWorker-1] Task scheduler.celery.debug_task[0d5a15ff-893f-40ce-b689-3a8b7e2f9259] succeeded in 0.060549805872142315s: None
[2019-11-12 16:15:21,138: INFO/ForkPoolWorker-1] Task celery.backend_cleanup[fa85ec7d-e579-48da-92f7-af0e7bd98214] succeeded in 0.07375145284458995s: None
[2019-11-12 16:43:46,080: INFO/ForkPoolWorker-1] Task celery.backend_cleanup[532547a7-89eb-4a1b-8c10-62a97b85bbb2] succeeded in 0.08247102797031403s: None
[2019-11-12 17:23:26,744: ERROR/ForkPoolWorker-1] Task task.tasks.ansible_hoc[6c359822-febd-4a39-9700-474aab12c51a] raised unexpected: A malformed block was encountered while loading tasks: [{'action':{'module':'shell','args':'mkdir -p /tmp/test123'}}] should be a list or None but is <class 'str'>
Traceback (most recent call last):
  File "/ddhome/cmdb/venv/lib64/python3.6/site-packages/ansible/playbook/play.py", line 146, in _load_tasks
    return load_list_of_blocks(ds=ds, play=self, variable_manager=self._variable_manager, loader=self._loader)
  File "/ddhome/cmdb/venv/lib64/python3.6/site-packages/ansible/playbook/helpers.py", line 44, in load_list_of_blocks
    raise AnsibleAssertionError('%s should be a list or None but is %s' % (ds, type(ds)))
ansible.errors.AnsibleAssertionError: [{'action':{'module':'shell','args':'mkdir -p /tmp/test123'}}] should be a list or None but is <class 'str'>

During handling of the above exception, another exception occurred:

Traceback (most recent call last):
  File "/ddhome/cmdb/venv/lib64/python3.6/site-packages/celery/app/trace.py", line 385, in trace_task
    R = retval = fun(*args, **kwargs)
  File "/ddhome/cmdb/venv/lib64/python3.6/site-packages/celery/app/trace.py", line 648, in __protected_call__
    return self.run(*args, **kwargs)
  File "/ddhome/cmdb/task/tasks.py", line 9, in ansible_hoc
    adhoc.task_run()
  File "/ddhome/cmdb/utils/AnsibleUtil.py", line 60, in task_run
    play = Play().load(play_source, variable_manager=self.variable_manager, loader=self.loader)
  File "/ddhome/cmdb/venv/lib64/python3.6/site-packages/ansible/playbook/play.py", line 115, in load
    return p.load_data(data, variable_manager=variable_manager, loader=loader)
  File "/ddhome/cmdb/venv/lib64/python3.6/site-packages/ansible/playbook/base.py", line 240, in load_data
    self._attributes[target_name] = method(name, ds[name])
  File "/ddhome/cmdb/venv/lib64/python3.6/site-packages/ansible/playbook/play.py", line 148, in _load_tasks
    raise AnsibleParserError("A malformed block was encountered while loading tasks: %s" % to_native(e), obj=self._ds, orig_exc=e)
ansible.errors.AnsibleParserError: A malformed block was encountered while loading tasks: [{'action':{'module':'shell','args':'mkdir -p /tmp/test123'}}] should be a list or None but is <class 'str'>
[2019-11-12 17:28:12,611: ERROR/ForkPoolWorker-1] Task task.tasks.ansible_hoc[14094d03-8a96-422d-bf74-726f4dcf63ef] raised unexpected: TypeError("__init__() got an unexpected keyword argument 'options'",)
Traceback (most recent call last):
  File "/ddhome/cmdb/venv/lib64/python3.6/site-packages/celery/app/trace.py", line 385, in trace_task
    R = retval = fun(*args, **kwargs)
  File "/ddhome/cmdb/venv/lib64/python3.6/site-packages/celery/app/trace.py", line 648, in __protected_call__
    return self.run(*args, **kwargs)
  File "/ddhome/cmdb/task/tasks.py", line 9, in ansible_hoc
    adhoc.task_run()
  File "/ddhome/cmdb/utils/AnsibleUtil.py", line 70, in task_run
    stdout_callback=self.results_callback,
TypeError: __init__() got an unexpected keyword argument 'options'
[2019-11-12 17:35:50,428: INFO/ForkPoolWorker-1] Task task.tasks.ansible_hoc[8e95b3f6-1e05-46af-9bef-eb2053540a08] succeeded in 0.7782944622449577s: {'ok': {}, 'failed': {}, 'unreachable': {}}
[2019-11-12 17:42:49,223: ERROR/ForkPoolWorker-1] Task task.tasks.ansible_hoc[7c7bffbb-c20b-4c41-9f6c-18ae7ad27b14] raised unexpected: A malformed block was encountered while loading a block
Traceback (most recent call last):
  File "/ddhome/cmdb/venv/lib64/python3.6/site-packages/ansible/playbook/block.py", line 129, in _load_block
    use_handlers=self._use_handlers,
  File "/ddhome/cmdb/venv/lib64/python3.6/site-packages/ansible/playbook/helpers.py", line 123, in load_list_of_tasks
    args_parser = ModuleArgsParser(task_ds)
  File "/ddhome/cmdb/venv/lib64/python3.6/site-packages/ansible/parsing/mod_args.py", line 114, in __init__
    raise AnsibleAssertionError("the type of 'task_ds' should be a dict, but is a %s" % type(task_ds))
ansible.errors.AnsibleAssertionError: the type of 'task_ds' should be a dict, but is a <class 'str'>

During handling of the above exception, another exception occurred:

Traceback (most recent call last):
  File "/ddhome/cmdb/venv/lib64/python3.6/site-packages/celery/app/trace.py", line 385, in trace_task
    R = retval = fun(*args, **kwargs)
  File "/ddhome/cmdb/venv/lib64/python3.6/site-packages/celery/app/trace.py", line 648, in __protected_call__
    return self.run(*args, **kwargs)
  File "/ddhome/cmdb/task/tasks.py", line 9, in ansible_hoc
    adhoc.task_run()
  File "/ddhome/cmdb/utils/AnsibleUtil.py", line 60, in task_run
    play = Play().load(play_source, variable_manager=self.variable_manager, loader=self.loader)
  File "/ddhome/cmdb/venv/lib64/python3.6/site-packages/ansible/playbook/play.py", line 112, in load
    return p.load_data(data, variable_manager=variable_manager, loader=loader)
  File "/ddhome/cmdb/venv/lib64/python3.6/site-packages/ansible/playbook/base.py", line 230, in load_data
    self._attributes[target_name] = method(name, ds[name])
  File "/ddhome/cmdb/venv/lib64/python3.6/site-packages/ansible/playbook/play.py", line 143, in _load_tasks
    return load_list_of_blocks(ds=ds, play=self, variable_manager=self._variable_manager, loader=self._loader)
  File "/ddhome/cmdb/venv/lib64/python3.6/site-packages/ansible/playbook/helpers.py", line 80, in load_list_of_blocks
    loader=loader,
  File "/ddhome/cmdb/venv/lib64/python3.6/site-packages/ansible/playbook/block.py", line 93, in load
    return b.load_data(data, variable_manager=variable_manager, loader=loader)
  File "/ddhome/cmdb/venv/lib64/python3.6/site-packages/ansible/playbook/base.py", line 230, in load_data
    self._attributes[target_name] = method(name, ds[name])
  File "/ddhome/cmdb/venv/lib64/python3.6/site-packages/ansible/playbook/block.py", line 132, in _load_block
    raise AnsibleParserError("A malformed block was encountered while loading a block", obj=self._ds, orig_exc=e)
ansible.errors.AnsibleParserError: A malformed block was encountered while loading a block
[2019-11-12 17:44:53,319: ERROR/ForkPoolWorker-1] Task task.tasks.ansible_hoc[f7bc615c-a6da-4335-afb6-080aa87fa88f] raised unexpected: JSONDecodeError('Expecting property name enclosed in double quotes: line 1 column 3 (char 2)',)
Traceback (most recent call last):
  File "/ddhome/cmdb/venv/lib64/python3.6/site-packages/celery/app/trace.py", line 385, in trace_task
    R = retval = fun(*args, **kwargs)
  File "/ddhome/cmdb/venv/lib64/python3.6/site-packages/celery/app/trace.py", line 648, in __protected_call__
    return self.run(*args, **kwargs)
  File "/ddhome/cmdb/task/tasks.py", line 8, in ansible_hoc
    adhoc = AnsibleRun(host_list, task_list)
  File "/ddhome/cmdb/utils/AnsibleUtil.py", line 49, in __init__
    self.task_list = json.loads(task_list)
  File "/usr/lib64/python3.6/json/__init__.py", line 354, in loads
    return _default_decoder.decode(s)
  File "/usr/lib64/python3.6/json/decoder.py", line 339, in decode
    obj, end = self.raw_decode(s, idx=_w(s, 0).end())
  File "/usr/lib64/python3.6/json/decoder.py", line 355, in raw_decode
    obj, end = self.scan_once(s, idx)
json.decoder.JSONDecodeError: Expecting property name enclosed in double quotes: line 1 column 3 (char 2)
[2019-11-12 17:47:03,821: ERROR/ForkPoolWorker-1] Task task.tasks.ansible_hoc[89524dab-2c7b-4d4c-b3f6-0f6438bb885d] raised unexpected: A malformed block was encountered while loading tasks
Traceback (most recent call last):
  File "/ddhome/cmdb/venv/lib64/python3.6/site-packages/ansible/playbook/play.py", line 143, in _load_tasks
    return load_list_of_blocks(ds=ds, play=self, variable_manager=self._variable_manager, loader=self._loader)
  File "/ddhome/cmdb/venv/lib64/python3.6/site-packages/ansible/playbook/helpers.py", line 47, in load_list_of_blocks
    raise AnsibleAssertionError('%s should be a list or None but is %s' % (ds, type(ds)))
ansible.errors.AnsibleAssertionError: [{'action': {'module': 'shell','args': 'mkdir -p /tmp/test123'}}] should be a list or None but is <class 'str'>

During handling of the above exception, another exception occurred:

Traceback (most recent call last):
  File "/ddhome/cmdb/venv/lib64/python3.6/site-packages/celery/app/trace.py", line 385, in trace_task
    R = retval = fun(*args, **kwargs)
  File "/ddhome/cmdb/venv/lib64/python3.6/site-packages/celery/app/trace.py", line 648, in __protected_call__
    return self.run(*args, **kwargs)
  File "/ddhome/cmdb/task/tasks.py", line 9, in ansible_hoc
    adhoc.task_run()
  File "/ddhome/cmdb/utils/AnsibleUtil.py", line 61, in task_run
    play = Play().load(play_source, variable_manager=self.variable_manager, loader=self.loader)
  File "/ddhome/cmdb/venv/lib64/python3.6/site-packages/ansible/playbook/play.py", line 112, in load
    return p.load_data(data, variable_manager=variable_manager, loader=loader)
  File "/ddhome/cmdb/venv/lib64/python3.6/site-packages/ansible/playbook/base.py", line 230, in load_data
    self._attributes[target_name] = method(name, ds[name])
  File "/ddhome/cmdb/venv/lib64/python3.6/site-packages/ansible/playbook/play.py", line 145, in _load_tasks
    raise AnsibleParserError("A malformed block was encountered while loading tasks", obj=self._ds, orig_exc=e)
ansible.errors.AnsibleParserError: A malformed block was encountered while loading tasks
[2019-11-12 17:55:36,791: ERROR/ForkPoolWorker-1] Task task.tasks.ansible_hoc[886e8727-c831-4992-b3ad-3a62af4311e2] raised unexpected: A malformed block was encountered while loading tasks
Traceback (most recent call last):
  File "/ddhome/cmdb/venv/lib64/python3.6/site-packages/ansible/playbook/play.py", line 143, in _load_tasks
    return load_list_of_blocks(ds=ds, play=self, variable_manager=self._variable_manager, loader=self._loader)
  File "/ddhome/cmdb/venv/lib64/python3.6/site-packages/ansible/playbook/helpers.py", line 47, in load_list_of_blocks
    raise AnsibleAssertionError('%s should be a list or None but is %s' % (ds, type(ds)))
ansible.errors.AnsibleAssertionError: [{'action': {'module': 'shell','args': 'mkdir -p /tmp/test123'}}] should be a list or None but is <class 'str'>

During handling of the above exception, another exception occurred:

Traceback (most recent call last):
  File "/ddhome/cmdb/venv/lib64/python3.6/site-packages/celery/app/trace.py", line 385, in trace_task
    R = retval = fun(*args, **kwargs)
  File "/ddhome/cmdb/venv/lib64/python3.6/site-packages/celery/app/trace.py", line 648, in __protected_call__
    return self.run(*args, **kwargs)
  File "/ddhome/cmdb/task/tasks.py", line 9, in ansible_hoc
    adhoc.task_run()
  File "/ddhome/cmdb/utils/AnsibleUtil.py", line 61, in task_run
    play = Play().load(play_source, variable_manager=self.variable_manager, loader=self.loader)
  File "/ddhome/cmdb/venv/lib64/python3.6/site-packages/ansible/playbook/play.py", line 112, in load
    return p.load_data(data, variable_manager=variable_manager, loader=loader)
  File "/ddhome/cmdb/venv/lib64/python3.6/site-packages/ansible/playbook/base.py", line 230, in load_data
    self._attributes[target_name] = method(name, ds[name])
  File "/ddhome/cmdb/venv/lib64/python3.6/site-packages/ansible/playbook/play.py", line 145, in _load_tasks
    raise AnsibleParserError("A malformed block was encountered while loading tasks", obj=self._ds, orig_exc=e)
ansible.errors.AnsibleParserError: A malformed block was encountered while loading tasks
[2019-11-12 18:04:37,940: ERROR/ForkPoolWorker-1] Task task.tasks.ansible_hoc[c59cc5c3-0e0b-4f7a-9cd6-c02153c07120] raised unexpected: A malformed block was encountered while loading tasks
Traceback (most recent call last):
  File "/ddhome/cmdb/venv/lib64/python3.6/site-packages/ansible/playbook/play.py", line 143, in _load_tasks
    return load_list_of_blocks(ds=ds, play=self, variable_manager=self._variable_manager, loader=self._loader)
  File "/ddhome/cmdb/venv/lib64/python3.6/site-packages/ansible/playbook/helpers.py", line 47, in load_list_of_blocks
    raise AnsibleAssertionError('%s should be a list or None but is %s' % (ds, type(ds)))
ansible.errors.AnsibleAssertionError: [{'action': {'module': 'shell','args': 'mkdir -p /tmp/test123'}}] should be a list or None but is <class 'str'>

During handling of the above exception, another exception occurred:

Traceback (most recent call last):
  File "/ddhome/cmdb/venv/lib64/python3.6/site-packages/celery/app/trace.py", line 385, in trace_task
    R = retval = fun(*args, **kwargs)
  File "/ddhome/cmdb/venv/lib64/python3.6/site-packages/celery/app/trace.py", line 648, in __protected_call__
    return self.run(*args, **kwargs)
  File "/ddhome/cmdb/task/tasks.py", line 9, in ansible_hoc
    adhoc.task_run()
  File "/ddhome/cmdb/utils/AnsibleUtil.py", line 61, in task_run
    play = Play().load(play_source, variable_manager=self.variable_manager, loader=self.loader)
  File "/ddhome/cmdb/venv/lib64/python3.6/site-packages/ansible/playbook/play.py", line 112, in load
    return p.load_data(data, variable_manager=variable_manager, loader=loader)
  File "/ddhome/cmdb/venv/lib64/python3.6/site-packages/ansible/playbook/base.py", line 230, in load_data
    self._attributes[target_name] = method(name, ds[name])
  File "/ddhome/cmdb/venv/lib64/python3.6/site-packages/ansible/playbook/play.py", line 145, in _load_tasks
    raise AnsibleParserError("A malformed block was encountered while loading tasks", obj=self._ds, orig_exc=e)
ansible.errors.AnsibleParserError: A malformed block was encountered while loading tasks
[2019-11-12 18:29:16,310: ERROR/ForkPoolWorker-1] Task task.tasks.ansible_hoc[78fe672a-7080-4240-b5da-b43b9261a6e2] raised unexpected: NameError("name 'module' is not defined",)
Traceback (most recent call last):
  File "/ddhome/cmdb/venv/lib64/python3.6/site-packages/celery/app/trace.py", line 385, in trace_task
    R = retval = fun(*args, **kwargs)
  File "/ddhome/cmdb/venv/lib64/python3.6/site-packages/celery/app/trace.py", line 648, in __protected_call__
    return self.run(*args, **kwargs)
  File "/ddhome/cmdb/task/tasks.py", line 9, in ansible_hoc
    adhoc.task_run()
  File "/ddhome/cmdb/utils/AnsibleUtil.py", line 58, in task_run
    dict(action=dict(module='{module}'.format(module=module), args="{args}".format(args=args))),
NameError: name 'module' is not defined
[2019-11-12 18:31:19,607: INFO/ForkPoolWorker-1] Task task.tasks.ansible_hoc[8298fd61-7827-4685-9723-515aa9288093] succeeded in 0.7781723961234093s: {'ok': {}, 'failed': {}, 'unreachable': {}}
[2019-11-12 18:37:14,733: WARNING/ForkPoolWorker-1] <bound method AnsibleRun.get_result of <utils.AnsibleUtil.AnsibleRun object at 0x7f4b4f33e710>>
[2019-11-12 18:37:14,848: INFO/ForkPoolWorker-1] Task task.tasks.ansible_hoc[af654ab5-d882-4519-9ba0-63c1a5ee35d5] succeeded in 0.7748140310868621s: {'ok': {}, 'failed': {}, 'unreachable': {}}
[2019-11-12 18:46:42,899: INFO/ForkPoolWorker-1] Task task.tasks.ansible_hoc[6420056c-7ffb-4a42-bc2d-ad6ce881cd45] succeeded in 0.725506919901818s: {'ok': {}, 'failed': {}, 'unreachable': {}}
[2019-11-12 18:48:17,076: INFO/ForkPoolWorker-1] Task task.tasks.ansible_hoc[18d4844c-2f6b-4938-ab2f-26fefd22d072] succeeded in 0.750036281067878s: {'ok': {}, 'failed': {}, 'unreachable': {}}
[2019-11-12 19:03:56,689: ERROR/ForkPoolWorker-1] Task task.tasks.ansible_hoc[32dccee3-633b-44ef-bce8-2f0db752365d] raised unexpected: AttributeError("'MyTaskQueueManager' object has no attribute '_workers'",)
Traceback (most recent call last):
  File "/ddhome/cmdb/venv/lib64/python3.6/site-packages/celery/app/trace.py", line 385, in trace_task
    R = retval = fun(*args, **kwargs)
  File "/ddhome/cmdb/venv/lib64/python3.6/site-packages/celery/app/trace.py", line 648, in __protected_call__
    return self.run(*args, **kwargs)
  File "/ddhome/cmdb/task/tasks.py", line 9, in ansible_hoc
    adhoc.task_run()
  File "/ddhome/cmdb/utils/AnsibleUtil.py", line 85, in task_run
    tqm.run(play)
  File "/ddhome/cmdb/venv/lib64/python3.6/site-packages/ansible/executor/task_queue_manager.py", line 267, in run
    self._initialize_processes(min(self._options.forks, iterator.batch_size))
  File "/ddhome/cmdb/utils/AnsibleUtil.py", line 42, in _initialize_processes
    self._workers.append([None, rslt_q])
AttributeError: 'MyTaskQueueManager' object has no attribute '_workers'
[2019-11-12 19:05:29,965: ERROR/ForkPoolWorker-1] Task task.tasks.ansible_hoc[5014c935-8a2a-436a-bf9d-d9890bf62ffb] raised unexpected: AttributeError("'list' object has no attribute 'is_alive'",)
Traceback (most recent call last):
  File "/ddhome/cmdb/utils/AnsibleUtil.py", line 85, in task_run
    tqm.run(play)
  File "/ddhome/cmdb/venv/lib64/python3.6/site-packages/ansible/executor/task_queue_manager.py", line 291, in run
    play_return = strategy.run(iterator, play_context)
  File "/ddhome/cmdb/venv/lib64/python3.6/site-packages/ansible/plugins/strategy/linear.py", line 310, in run
    self._queue_task(host, task, task_vars, play_context)
  File "/ddhome/cmdb/venv/lib64/python3.6/site-packages/ansible/plugins/strategy/__init__.py", line 312, in _queue_task
    if worker_prc is None or not worker_prc.is_alive():
AttributeError: 'list' object has no attribute 'is_alive'

During handling of the above exception, another exception occurred:

Traceback (most recent call last):
  File "/ddhome/cmdb/venv/lib64/python3.6/site-packages/celery/app/trace.py", line 385, in trace_task
    R = retval = fun(*args, **kwargs)
  File "/ddhome/cmdb/venv/lib64/python3.6/site-packages/celery/app/trace.py", line 648, in __protected_call__
    return self.run(*args, **kwargs)
  File "/ddhome/cmdb/task/tasks.py", line 9, in ansible_hoc
    adhoc.task_run()
  File "/ddhome/cmdb/utils/AnsibleUtil.py", line 88, in task_run
    tqm.cleanup()
  File "/ddhome/cmdb/venv/lib64/python3.6/site-packages/ansible/executor/task_queue_manager.py", line 305, in cleanup
    self._cleanup_processes()
  File "/ddhome/cmdb/venv/lib64/python3.6/site-packages/ansible/executor/task_queue_manager.py", line 310, in _cleanup_processes
    if worker_prc and worker_prc.is_alive():
AttributeError: 'list' object has no attribute 'is_alive'
[2019-11-12 19:15:28,772: INFO/ForkPoolWorker-1] Task task.tasks.ansible_hoc[66d3b304-fa0c-4444-b043-a56ebe44b5a7] succeeded in 2.120634767692536s: {'ok': {'192.168.66.92': {'changed': True, 'end': '2019-11-12 19:15:28.608115', 'stdout': '', 'cmd': 'mkdir /tmp/test123', 'rc': 0, 'start': '2019-11-12 19:15:28.580491', 'stderr': '', 'delta': '0:00:00.027624', 'invocation': {...}, 'warnings': [...], '_ansible_parsed': True, 'stdout_lines': [...], 'stderr_lines': [...], '_ansible_no_log': False}, 'runner': 'ok'}, 'failed': {}, 'unreachable': {}}
[2019-11-12 19:20:58,161: INFO/ForkPoolWorker-1] Task task.tasks.ansible_hoc[648f1dee-7577-441c-8ba3-d9ad4a93cf99] succeeded in 1.1891109286807477s: {'ok': {}, 'failed': {}, 'unreachable': {}}
[2019-11-12 19:21:26,145: INFO/ForkPoolWorker-1] Task task.tasks.ansible_hoc[6bf975fe-7da4-4792-96bf-0dced17abc14] succeeded in 1.4007005142048001s: {'ok': {}, 'failed': {}, 'unreachable': {}}
[2019-11-12 19:25:58,064: INFO/ForkPoolWorker-1] Task task.tasks.ansible_hoc[0bdc398e-4650-4383-8c9c-ab28dae37c76] succeeded in 1.2277990807779133s: {'ok': {}, 'failed': {}, 'unreachable': {}}
[2019-11-12 21:20:20,063: INFO/ForkPoolWorker-1] Task task.tasks.ansible_hoc[82b2f1ac-6c7b-4d3f-a44c-5da9fea4f0ba] succeeded in 1.8205494531430304s: {'ok': {}, 'failed': {}, 'unreachable': {}}
[2019-11-12 21:20:55,139: INFO/ForkPoolWorker-1] Task task.tasks.ansible_hoc[0686019d-680a-4250-bf1d-781bde6139a9] succeeded in 0.7472091680392623s: {'ok': {}, 'failed': {}, 'unreachable': {}}
[2019-11-12 21:27:08,133: INFO/ForkPoolWorker-1] Task task.tasks.ansible_hoc[7e8581c1-14ad-486b-8642-a3514488c11c] succeeded in 1.8307745661586523s: {'ok': {}, 'failed': {}, 'unreachable': {}}
[2019-11-12 21:27:52,963: INFO/ForkPoolWorker-1] Task task.tasks.ansible_hoc[05577264-ba96-4868-8f55-892dcada969a] succeeded in 1.3946907729841769s: {'ok': {}, 'failed': {}, 'unreachable': {}}
[2019-11-12 21:35:16,811: INFO/ForkPoolWorker-1] Task task.tasks.ansible_hoc[ee38ed81-dd89-49d9-a2ed-235321e38f6c] succeeded in 1.841510966885835s: {'ok': {}, 'failed': {}, 'unreachable': {}}
[2019-11-12 21:45:10,026: INFO/ForkPoolWorker-1] Task task.tasks.ansible_hoc[06c0a741-37fe-45d4-affc-d86b417fd8f8] succeeded in 0.8395616551861167s: {'ok': {}, 'failed': {}, 'unreachable': {'192.168.66.255': {'unreachable': True, 'msg': 'Failed to connect to the host via ssh: ssh: connect to host 192.168.66.255 port 22: Network is unreachable', 'changed': False}, 'runner': 'unreachable'}}
[2019-11-12 21:50:48,011: INFO/ForkPoolWorker-1] Task task.tasks.ansible_hoc[99997c85-c944-43cd-a7b9-689bfebdec0b] succeeded in 1.7584205772727728s: {'ok': {}, 'failed': {}, 'unreachable': {}}
[2019-11-12 21:54:14,276: INFO/ForkPoolWorker-1] Task task.tasks.ansible_hoc[ec4cd18f-b197-4447-95b9-4bf14f634051] succeeded in 1.4067425248213112s: {'ok': {}, 'failed': {'192.168.66.92': {'changed': True, 'end': '2019-11-12 21:54:14.131378', 'stdout': '', 'cmd': 'r', 'delta': '0:00:00.027236', 'stderr': '/bin/sh: r: command not found', 'rc': 127, 'invocation': {...}, 'start': '2019-11-12 21:54:14.104142', 'msg': 'non-zero return code', '_ansible_parsed': True, 'stdout_lines': [...], 'stderr_lines': [...], '_ansible_no_log': False}, 'runner': 'failed'}, 'unreachable': {}}
[2019-11-13 09:58:44,557: WARNING/ForkPoolWorker-1] 192.168.66.92,
[2019-11-13 09:58:44,558: WARNING/ForkPoolWorker-1] <class 'str'>
[2019-11-13 09:58:44,558: WARNING/ForkPoolWorker-1] [{'action': {'module': 'shell', 'args': 'mkdir -p /tmp/test123'}}]
[2019-11-13 09:58:44,558: WARNING/ForkPoolWorker-1] <class 'list'>
[2019-11-13 09:58:45,945: INFO/ForkPoolWorker-1] Task task.tasks.ansible_hoc[0f9d50c1-fff1-4358-8ab2-d0508b2d9310] succeeded in 1.3879738398827612s: {'ok': {'192.168.66.92': {'changed': True, 'end': '2019-11-13 09:58:45.808690', 'stdout': '', 'cmd': 'mkdir -p /tmp/test123', 'rc': 0, 'start': '2019-11-13 09:58:45.780992', 'stderr': '', 'delta': '0:00:00.027698', 'invocation': {...}, 'warnings': [...], '_ansible_parsed': True, 'stdout_lines': [...], 'stderr_lines': [...], '_ansible_no_log': False}, 'runner': 'ok'}, 'failed': {}, 'unreachable': {}}
[2019-11-13 10:03:07,108: WARNING/ForkPoolWorker-1] 192.168.66.92,
[2019-11-13 10:03:07,108: WARNING/ForkPoolWorker-1] <class 'str'>
[2019-11-13 10:03:07,109: WARNING/ForkPoolWorker-1] [{'action': {'module': 'shell', 'args': 'mkdir -p /tmp/test123'}}, {'action': {'module': 'shell', 'args': 'mkdir -p /tmp/test345'}}]
[2019-11-13 10:03:07,109: WARNING/ForkPoolWorker-1] <class 'list'>
[2019-11-13 10:03:08,743: INFO/ForkPoolWorker-1] Task task.tasks.ansible_hoc[36758f4e-051b-4291-984f-070212840f4a] succeeded in 1.6360992370173335s: {'ok': {'192.168.66.92': {'changed': True, 'end': '2019-11-13 10:03:08.664793', 'stdout': '', 'cmd': 'mkdir -p /tmp/test345', 'rc': 0, 'start': '2019-11-13 10:03:08.636285', 'stderr': '', 'delta': '0:00:00.028508', 'invocation': {...}, 'warnings': [...], '_ansible_parsed': True, 'stdout_lines': [...], 'stderr_lines': [...], '_ansible_no_log': False}, 'runner': 'ok'}, 'failed': {}, 'unreachable': {}}
[2019-11-13 14:23:29,625: WARNING/ForkPoolWorker-1] 192.168.66.92,
[2019-11-13 14:23:29,626: WARNING/ForkPoolWorker-1] <class 'str'>
[2019-11-13 14:23:29,626: WARNING/ForkPoolWorker-1] [{'action': {'module': 'shell', 'args': 'mkdir -p /tmp/test123'}}, {'action': {'module': 'shell', 'args': 'rm -rf /tmp/test123'}}]
[2019-11-13 14:23:29,627: WARNING/ForkPoolWorker-1] <class 'list'>
[2019-11-13 14:23:32,144: INFO/ForkPoolWorker-1] Task task.tasks.ansible_hoc[c4680c06-5bf7-44c7-96e1-867fb2e2ec6c] succeeded in 2.518887204118073s: {'ok': [[], []], 'failed': [], 'unreachable': []}
[2019-11-13 14:40:41,892: INFO/ForkPoolWorker-1] Task task.tasks.ansible_hoc[1b588423-602b-4be4-b4cb-519db7b49b16] succeeded in 3.729832696262747s: {'ok': [[{...}, {...}], [{...}, {...}], [{...}, {...}]], 'failed': [], 'unreachable': []}
[2019-11-13 15:17:58,552: INFO/ForkPoolWorker-1] Task task.tasks.ansible_hoc[17d81f82-5a92-4e7c-a375-7afa510ba911] succeeded in 2.73131902795285s: {'ok': [[{...}, {...}], [{...}, {...}], [{...}, {...}]], 'failed': [], 'unreachable': []}
[2019-11-14 04:00:00,112: INFO/ForkPoolWorker-1] Task celery.backend_cleanup[8491c147-0e89-401b-8b7c-fec0002850c3] succeeded in 0.055675311014056206s: None
[2019-11-14 10:00:03,612: INFO/ForkPoolWorker-1] Task task.tasks.clean_image[dbc13bac-6b57-4f46-b438-2684bf795094] succeeded in 3.581287478096783s: {'ok': [], 'failed': [[{...}, {...}], [{...}, {...}], [{...}, {...}], [{...}, {...}], [{...}, {...}], [{...}, {...}], [{...}, {...}], [{...}, {...}], [{...}, {...}], [{...}, {...}], [{...}, {...}], [{...}, {...}], [{...}, {...}], [{...}, {...}]], 'unreachable': []}
[2019-11-14 17:06:59,913: INFO/ForkPoolWorker-1] Task task.tasks.ansible_hoc[e973dd6b-560e-4829-a6d3-95c6f3c30a1e] succeeded in 1.6689654849469662s: {'ok': [[{...}, {...}], [{...}, {...}], [{...}, {...}]], 'failed': [], 'unreachable': []}
[2019-11-15 04:00:00,159: INFO/ForkPoolWorker-1] Task celery.backend_cleanup[a8864dc6-face-468a-ba3c-e702be240c39] succeeded in 0.11894473480060697s: None
[2019-11-15 11:44:40,138: INFO/ForkPoolWorker-1] Task task.tasks.ansible_hoc[a79052e0-7984-4c21-8a80-ae37df021888] succeeded in 2.1445770650170743s: {'ok': [[{...}, {...}], [{...}, {...}], [{...}, {...}]], 'failed': [], 'unreachable': []}
[2019-11-15 17:34:03,115: INFO/ForkPoolWorker-1] Task task.tasks.ansible_hoc[cb0626d3-e15b-483b-b6ff-e57d584f6498] succeeded in 2.137375645339489s: {'ok': [[{...}, {...}], [{...}, {...}], [{...}, {...}]], 'failed': [], 'unreachable': []}
[2019-11-20 10:00:08,054: INFO/ForkPoolWorker-1] Task task.tasks.clean_image[4db3ca18-338e-4ca4-a767-1b21db3c9cb3] succeeded in 8.018534149043262s: {'ok': [], 'failed': [[{...}, {...}], [{...}, {...}], [{...}, {...}], [{...}, {...}], [{...}, {...}], [{...}, {...}], [{...}, {...}], [{...}, {...}], [{...}, {...}], [{...}, {...}], [{...}, {...}], [{...}, {...}], [{...}, {...}], [{...}, {...}], [{...}, {...}], [{...}, {...}], [{...}, {...}], [{...}, {...}], [{...}, {...}]], 'unreachable': []}
[2019-11-21 19:50:27,795: INFO/ForkPoolWorker-1] Task task.tasks.ansible_hoc[2e921184-6a72-47a5-97ee-03835f7e9d91] succeeded in 2.4909495040774345s: {'ok': [[{...}, {...}], [{...}, {...}], [{...}, {...}]], 'failed': [], 'unreachable': []}
[2019-11-22 14:21:24,025: INFO/ForkPoolWorker-1] Task task.tasks.ansible_hoc[069cbcfe-56e0-4b61-9ea2-58ea306a9f52] succeeded in 2.810675331391394s: {'ok': [[{...}, {...}], [{...}, {...}], [{...}, {...}]], 'failed': [], 'unreachable': []}
[2019-11-22 19:27:12,689: INFO/ForkPoolWorker-1] Task task.tasks.ansible_hoc[0a95c507-8828-4244-a7b5-c3a7d3bbc9fc] succeeded in 2.3467985475435853s: {'ok': [[{...}, {...}], [{...}, {...}], [{...}, {...}]], 'failed': [], 'unreachable': []}
[2019-11-25 14:05:42,896: INFO/ForkPoolWorker-1] Task task.tasks.ansible_hoc[1b7eb4de-09f5-4b82-84c5-56446a86b2a1] succeeded in 3.369597788900137s: {'ok': [[{...}, {...}], [{...}, {...}], [{...}, {...}]], 'failed': [], 'unreachable': []}
[2019-11-27 10:00:16,262: INFO/ForkPoolWorker-1] Task task.tasks.clean_image[d7fba364-266a-4b4d-a60e-9baf50685d6c] succeeded in 16.222585479728878s: {'ok': [], 'failed': [[{...}, {...}], [{...}, {...}], [{...}, {...}], [{...}, {...}], [{...}, {...}], [{...}, {...}], [{...}, {...}], [{...}, {...}], [{...}, {...}], [{...}, {...}], [{...}, {...}], [{...}, {...}], [{...}, {...}], [{...}, {...}], [{...}, {...}], [{...}, {...}], [{...}, {...}], [{...}, {...}], [{...}, {...}]], 'unreachable': []}
[2019-11-28 13:56:04,540: INFO/ForkPoolWorker-1] Task task.tasks.ansible_hoc[fbc6c74d-ac16-48f7-9ab6-882516562e9e] succeeded in 2.3652963815256953s: {'ok': [[{...}, {...}], [{...}, {...}], [{...}, {...}]], 'failed': [], 'unreachable': []}
